2024-04-12 04:00:36 - logger - ERROR - Uncaught exception
Traceback (most recent call last):
  File "/Users/lianaharvilla/Dropbox/Mac/Documents/GitHub/Quest_Master/bot_brewery.py", line 35, in <module>
    bot.add_cog(BotCommands(bot))
                ^^^^^^^^^^^^^^^^
TypeError: BotCommands.__init__() missing 2 required positional arguments: 'role_dict' and 'logger'
2024-04-12 04:00:36 - logger - ERROR - Uncaught exception
Traceback (most recent call last):
  File "/Users/lianaharvilla/Dropbox/Mac/Documents/GitHub/Quest_Master/bot_brewery.py", line 35, in <module>
    bot.add_cog(BotCommands(bot))
                ^^^^^^^^^^^^^^^^
TypeError: BotCommands.__init__() missing 2 required positional arguments: 'role_dict' and 'logger'
2024-04-12 04:00:36 - logger - ERROR - Uncaught exception
Traceback (most recent call last):
  File "/Users/lianaharvilla/Dropbox/Mac/Documents/GitHub/Quest_Master/bot_brewery.py", line 35, in <module>
    bot.add_cog(BotCommands(bot))
                ^^^^^^^^^^^^^^^^
TypeError: BotCommands.__init__() missing 2 required positional arguments: 'role_dict' and 'logger'
2024-04-12 04:00:36 - logger - ERROR - Uncaught exception
Traceback (most recent call last):
  File "/Users/lianaharvilla/Dropbox/Mac/Documents/GitHub/Quest_Master/bot_brewery.py", line 35, in <module>
    bot.add_cog(BotCommands(bot))
                ^^^^^^^^^^^^^^^^
TypeError: BotCommands.__init__() missing 2 required positional arguments: 'role_dict' and 'logger'
2024-04-12 04:04:44 - __main__ - ERROR - Uncaught exception
Traceback (most recent call last):
  File "/Users/lianaharvilla/Dropbox/Mac/Documents/GitHub/Quest_Master/bot_brewery.py", line 42, in <module>
    bot.event(lambda: on_ready(bot))
  File "/Library/Frameworks/Python.framework/Versions/3.11/lib/python3.11/site-packages/discord/client.py", line 1986, in event
    raise TypeError('event registered must be a coroutine function')
TypeError: event registered must be a coroutine function
2024-04-12 04:15:27 - __main__ - ERROR - Uncaught exception
Traceback (most recent call last):
  File "/Users/lianaharvilla/Dropbox/Mac/Documents/GitHub/Quest_Master/bot_brewery.py", line 72, in <module>
    asyncio.run(main())
  File "/Library/Frameworks/Python.framework/Versions/3.11/lib/python3.11/asyncio/runners.py", line 190, in run
    return runner.run(main)
           ^^^^^^^^^^^^^^^^
  File "/Library/Frameworks/Python.framework/Versions/3.11/lib/python3.11/asyncio/runners.py", line 118, in run
    return self._loop.run_until_complete(task)
           ^^^^^^^^^^^^^^^^^^^^^^^^^^^^^^^^^^^
  File "/Library/Frameworks/Python.framework/Versions/3.11/lib/python3.11/asyncio/base_events.py", line 654, in run_until_complete
    return future.result()
           ^^^^^^^^^^^^^^^
  File "/Users/lianaharvilla/Dropbox/Mac/Documents/GitHub/Quest_Master/bot_brewery.py", line 53, in main
    bot.add_cog(BotCommands(bot))
    ^^^
NameError: name 'bot' is not defined
2024-04-15 15:11:05 - __main__ - ERROR - Uncaught exception
Traceback (most recent call last):
  File "/Users/lianaharvilla/Dropbox/Mac/Documents/GitHub/Quest_Master/bot_brewery.py", line 165, in <module>
    asyncio.run(main())
  File "/Library/Frameworks/Python.framework/Versions/3.11/lib/python3.11/asyncio/runners.py", line 190, in run
    return runner.run(main)
           ^^^^^^^^^^^^^^^^
  File "/Library/Frameworks/Python.framework/Versions/3.11/lib/python3.11/asyncio/runners.py", line 118, in run
    return self._loop.run_until_complete(task)
           ^^^^^^^^^^^^^^^^^^^^^^^^^^^^^^^^^^^
  File "/Library/Frameworks/Python.framework/Versions/3.11/lib/python3.11/asyncio/base_events.py", line 654, in run_until_complete
    return future.result()
           ^^^^^^^^^^^^^^^
  File "/Users/lianaharvilla/Dropbox/Mac/Documents/GitHub/Quest_Master/bot_brewery.py", line 154, in main
    await bot.load_extension('cogs.bot_commands') # Load your commands extension
    ^^^^^^^^^^^^^^^^^^^^^^^^^^^^^^^^^^^^^^^^^^^^^
  File "/Library/Frameworks/Python.framework/Versions/3.11/lib/python3.11/site-packages/discord/ext/commands/bot.py", line 1011, in load_extension
    raise errors.ExtensionNotFound(name)
discord.ext.commands.errors.ExtensionNotFound: Extension 'cogs.bot_commands' could not be loaded.
2024-04-15 15:12:30 - __main__ - ERROR - Uncaught exception
Traceback (most recent call last):
  File "/Library/Frameworks/Python.framework/Versions/3.11/lib/python3.11/site-packages/discord/ext/commands/bot.py", line 947, in _load_from_module_spec
    await setup(self)
TypeError: object NoneType can't be used in 'await' expression

The above exception was the direct cause of the following exception:

Traceback (most recent call last):
  File "/Users/lianaharvilla/Dropbox/Mac/Documents/GitHub/Quest_Master/bot_brewery.py", line 165, in <module>
    asyncio.run(main())
  File "/Library/Frameworks/Python.framework/Versions/3.11/lib/python3.11/asyncio/runners.py", line 190, in run
    return runner.run(main)
           ^^^^^^^^^^^^^^^^
  File "/Library/Frameworks/Python.framework/Versions/3.11/lib/python3.11/asyncio/runners.py", line 118, in run
    return self._loop.run_until_complete(task)
           ^^^^^^^^^^^^^^^^^^^^^^^^^^^^^^^^^^^
  File "/Library/Frameworks/Python.framework/Versions/3.11/lib/python3.11/asyncio/base_events.py", line 654, in run_until_complete
    return future.result()
           ^^^^^^^^^^^^^^^
  File "/Users/lianaharvilla/Dropbox/Mac/Documents/GitHub/Quest_Master/bot_brewery.py", line 154, in main
    await bot.load_extension('cogs.bot_commands') # Load your commands extension
    ^^^^^^^^^^^^^^^^^^^^^^^^^^^^^^^^^^^^^^^^^^^^^
  File "/Library/Frameworks/Python.framework/Versions/3.11/lib/python3.11/site-packages/discord/ext/commands/bot.py", line 1013, in load_extension
    await self._load_from_module_spec(spec, name)
  File "/Library/Frameworks/Python.framework/Versions/3.11/lib/python3.11/site-packages/discord/ext/commands/bot.py", line 952, in _load_from_module_spec
    raise errors.ExtensionFailed(key, e) from e
discord.ext.commands.errors.ExtensionFailed: Extension 'cogs.bot_commands' raised an error: TypeError: object NoneType can't be used in 'await' expression
2024-04-15 15:34:00 - __main__ - ERROR - Uncaught exception
Traceback (most recent call last):
  File "/Library/Frameworks/Python.framework/Versions/3.11/lib/python3.11/site-packages/discord/ext/commands/bot.py", line 947, in _load_from_module_spec
    await setup(self)
TypeError: object NoneType can't be used in 'await' expression

The above exception was the direct cause of the following exception:

Traceback (most recent call last):
  File "/Users/lianaharvilla/Dropbox/Mac/Documents/GitHub/Quest_Master/bot_brewery.py", line 159, in <module>
    asyncio.run(main())
  File "/Library/Frameworks/Python.framework/Versions/3.11/lib/python3.11/asyncio/runners.py", line 190, in run
    return runner.run(main)
           ^^^^^^^^^^^^^^^^
  File "/Library/Frameworks/Python.framework/Versions/3.11/lib/python3.11/asyncio/runners.py", line 118, in run
    return self._loop.run_until_complete(task)
           ^^^^^^^^^^^^^^^^^^^^^^^^^^^^^^^^^^^
  File "/Library/Frameworks/Python.framework/Versions/3.11/lib/python3.11/asyncio/base_events.py", line 654, in run_until_complete
    return future.result()
           ^^^^^^^^^^^^^^^
  File "/Users/lianaharvilla/Dropbox/Mac/Documents/GitHub/Quest_Master/bot_brewery.py", line 138, in main
    await bot.load_extension('cogs.help_command') # Load your help command extension
    ^^^^^^^^^^^^^^^^^^^^^^^^^^^^^^^^^^^^^^^^^^^^^
  File "/Library/Frameworks/Python.framework/Versions/3.11/lib/python3.11/site-packages/discord/ext/commands/bot.py", line 1013, in load_extension
    await self._load_from_module_spec(spec, name)
  File "/Library/Frameworks/Python.framework/Versions/3.11/lib/python3.11/site-packages/discord/ext/commands/bot.py", line 952, in _load_from_module_spec
    raise errors.ExtensionFailed(key, e) from e
discord.ext.commands.errors.ExtensionFailed: Extension 'cogs.help_command' raised an error: TypeError: object NoneType can't be used in 'await' expression
